Workbook

Sheet README
B1: GALACTIC BUREAUCRACY — Economy Model v0.2
B2: Idle / incremental economy backbone. Tune the BLUE cells; everything else recalculates.
B4: HOW TO USE
B5: • BLUE cells on yellow background = inputs you tune. BLACK cells = formulas, don't touch.
B6: • Green cells pull from other sheets.
B7: • After editing in Excel, values auto-recalc. In LibreOffice/Sheets, same.
B9: SHEET GUIDE
B10: 1. README — this page.
B11: 2. Assumptions — global knobs: tick rate, currency definitions, growth constants.
B12: 3. Vassals — the full vassal roster with cost curves & production. Core of the game.
B13: 4. CostCurve_Sim — buy levels 0..50 of a vassal, see cost & cumulative cost ramp.
B14: 5. Production_Sim — minute-by-minute Cyber Crystal economy over a session.
... B29: • Only real strategic choice = which region to conquer (Sun Drips vs Pepper Melange).

Sheet Assumptions
B1: GLOBAL ASSUMPTIONS
B2: Yellow = key knobs. Change these to rebalance the whole model.
B4: Parameter | C4: Value | D4: Unit | E4: Notes / why it matters
B5: Tick rate | C5: 1 | D5: ticks/sec | E5: Production resolves per second. Keep at 1 for design clarity.
B6: Session length (active) | C6: 5 | D6: minutes | E6: Typical active session for ADHD-first design. Used in Production_Sim.
B7: Offline cap | C7: 8 | D7: hours | E7: Max offline accrual. A return trigger, NOT a punishment (Gamigion 2025).
B8: Offline efficiency | C8: 0.5 | D8: x | E8: Offline earns this fraction of online rate. 0.5 = half-rate while away.
B9: Global cost multiplier | C9: 1.1 | D9: x | E9: DEFAULT growth base for cost curves. 1.07=gentle (Clicker Heroes), 1.15=steep (Cookie Clicker).
B10: Manual click yield | C10: 1 | D10: CC/click | E10: 1 CC/tap. Real players mash 5-8 taps/s -> first vassal in ~8s. Manual phase is intentionally tiny.
B11: Prestige curve power | C11: 0.5 | D11: exp | E11: Stamp = (LifetimeCC / divisor) ^ power. 0.5 = sqrt = strong diminishing returns.
B12: Prestige divisor | C12: 1000000000 | D12: CC | E12: Lowered so stamps accrue often. Stamp=(lifetimeCC/div)^power.
B13: Stamp buff per stamp | C13: 0.6 | D13: x/stamp | E13: +2% each, but stamps are far more plentiful (low divisor) -> frequent dopamine ticks.
B14: Rewarded ad multiplier | C14: 2 | D14: x | E14: Watch ad -> double offline haul or skip a war timer (MAF: rewarded video is key format).
B17: CURRENCY LEGEND
B18: Currency | C18: Role | D18: Tier | E18: Source
B19: Cyber Crystal (CC) | C19: Main currency | D19: Core | E19: Everything; vassal production
B20: Sun Drips | C20: Aux resource | D20: Core | E20: Only certain regions produce it
B21: Pepper Melange | C21: Aux resource | D21: Core | E21: Only certain regions produce it
B22: Red Pill | C22: War currency | D22: Conquest | E22: Used to enlist Mech-Bros
B23: Mech-Bro | C23: War unit | D23: Conquest | E23: Disposable; enlisted with Red Pill
B24: Abdication Stamp | C24: Prestige unit | D24: Prestige | E24: Earned on prestige; permanent buff
B25: Dark Matter | C25: Mid-game special | D25: Prestige | E25: Function TBD (open question)
B27: WAR / GALAXY ASSUMPTIONS
B28: Parameter | C28: Value | D28: Unit | E28: Notes / why it matters
B29: Base war timer (hrs) | C29: 6 | D29: hours | E29: Tier-1 conquest timer. Scales up by tier. Test 6-16h.
B30: Red Pill per Mech-Bro | C30: 25 | D30: RedPill | E30: Enlist cost per unit before discounts.
B31: Tier cost scale | C31: 4 | D31: x | E31: Each sector tier multiplies Red Pill/Mech-Bro need by this. Big number = weeks to clear.
B32: Tier output scale | C32: 3 | D32: x | E32: Each tier multiplies region resource output. Slightly < cost scale -> later sectors are a stretch.
B33: Tier timer scale | C33: 1.5 | D33: x | E33: Each tier multiplies war timer. Outer sectors take much longer.
B34: Sector unlock % | C34: 0.6 | D34: % | E34: Must conquer this fraction of a sector's regions to unlock the next.
B35: Sun Drips -> CC boost | C35: 0.005 | D35: x per unit/s | E35: TINY global boost (0.5%/drip) as a deliberate lever toward prestige threshold. NOT the old +10% runaway.
B36: Melange -> compound rate | C36: 0.05 | D36: x per unit/s | E36: Each Melange/sec converts CC into compound tier at this rate (feeds late CC).
B37: Galaxy total regions | C37: 50 | D37: regions | E37: Total conquerable regions across all sectors. Big = full conquest takes weeks.
B39: FLEET / TRANSIT VISA ASSUMPTIONS
B40: Parameter | C40: Value | D40: Unit | E40: Notes
B41: CC per Transit Visa | C41: 100 | D41: CC/Visa | E41: Steep conversion. Transit Visas gate the fleet. Comedy: paperwork, not physics.
B42: Connection buff per link | C42: 0.03 | D42: x/link | E42: Per-system, LOCAL buff to that system's own output. Not global.
B43: Max links counted/system | C43: 3 | D43: links | E43: Per-system cap. A system benefits from at most its 3 strongest links.
B44: Supply-line bonus (linked same-type) | C44: 0.05 | D44: x/pair | E44: +5% when two conquered Sun Drips systems are connected to each other. Rewards contiguous territory.
B45: Upgrade cost growth | C45: 2 | D45: x/level | E45: Each upgrade level costs this much more. 2x = impactful, finite-feeling.
...

Sheet Vassals
B1: VASSAL ROSTER
B2: Each vassal: base cost, per-vassal cost multiplier, production. Manual until first owned -> then automated.
B4: Vassal | C4: Base Cost | D4: Cost Mult | E4: Produces | F4: Base Output | G4: Output Unit | H4: Unlock Req | I4: Notes
B5: Lord Formsworth III | C5: 50 | D5: 1.1 | E5: Cyber Crystal | F5: 1.5 | G5: CC/sec | H5: 0 | I5: 40 yrs filling one form. Entry automation.
B6: Sun Scraper Brglx | C6: 500 | D6: 1.1 | E6: Sun Drips | F6: 2 | G6: Drips/sec | H6: 10 | I6: Needs 10 Formsworth. Automates Sun Drips.
B7: Pepper Bakani Zyx | C7: 1500 | D7: 1.1 | E7: Pepper Melange | F7: 2.5 | G7: Melange/sec | H7: 0 | I7: +20% melange + region harvest auto.
B8: Drood Komutani Vrrk | C8: 4000 | D8: 1.1 | E8: War Speed | F8: 3 | G8: hrs cut | H8: 0 | I8: Cuts war timer -3h. Not CC.
B9: Galaktik HR Muduru | C9: 8000 | D9: 1.1 | E9: Red Pill Disc | F9: 0.15 | G9: cost -% | H9: 0 | I9: Red Pill cost -15%.
B10: Abdication Arsivisti | C10: 25000 | D10: 1.1 | E10: Stamp Bonus | F10: 1 | G10: stamp +1 | H10: 0 | I10: +1 Abdication Stamp per prestige.
B13: Cost of Nth copy = Base Cost x Cost Mult ^ (copies already owned). See CostCurve_Sim.

Sheet CostCurve_Sim
B1: COST CURVE SIMULATOR
B2: Pick a vassal's base cost & multiplier below; see how buying 0..50 copies ramps cost.
B4: Base Cost | C4: =Vassals!C5 | D4: (linked to Lord Formsworth III by default)
B5: Cost Multiplier | C5: =Vassals!D5
B7: Copies Owned | C7: Cost of Next | D7: Cumulative Cost | E7: Output @ level | F7: Sec to afford next
B8: 0 | C8: =$C$4*$C$5^B8 | D8: =C8 | E8: =(B8+1)*Vassals!$F$5 | F8: =C8/Vassals!$F$5
B9: 1 | C9: =$C$4*$C$5^B9 | D9: =D8+C9 | E9: =(B9+1)*Vassals!$F$5 | F9: =C9/((B9)*Vassals!$F$5)
B10: 2 | C10: =$C$4*$C$5^B10 | D10: =D9+C10 | E10: =(B10+1)*Vassals!$F$5 | F10: =C10/((B10)*Vassals!$F$5)
B11: 3 | C11: =$C$4*$C$5^B11 | D11: =D10+C11 | E11: =(B11+1)*Vassals!$F$5 | F11: =C11/((B11)*Vassals!$F$5)
B12: 4 | C12: =$C$4*$C$5^B12 | D12: =D11+C12 | E12: =(B12+1)*Vassals!$F$5 | F12: =C12/((B12)*Vassals!$F$5)
B13: 5 | C13: =$C$4*$C$5^B13 | D13: =D12+C13 | E13: =(B13+1)*Vassals!$F$5 | F13: =C13/((B13)*Vassals!$F$5)
B14: 6 | C14: =$C$4*$C$5^B14 | D14: =D13+C14 | E14: =(B14+1)*Vassals!$F$5 | F14: =C14/((B14)*Vassals!$F$5)
B15: 7 | C15: =$C$4*$C$5^B15 | D15: =D14+C15 | E15: =(B15+1)*Vassals!$F$5 | F15: =C15/((B15)*Vassals!$F$5)
B16: 8 | C16: =$C$4*$C$5^B16 | D16: =D15+C16 | E16: =(B16+1)*Vassals!$F$5 | F16: =C16/((B16)*Vassals!$F$5)
B17: 9 | C17: =$C$4*$C$5^B17 | D17: =D16+C17 | E17: =(B17+1)*Vassals!$F$5 | F17: =C17/((B17)*Vassals!$F$5)
B18: 10 | C18: =$C$4*$C$5^B18 | D18: =D17+C18 | E18: =(B18+1)*Vassals!$F$5 | F18: =C18/((B18)*Vassals!$F$5)
B19: 11 | C19: =$C$4*$C$5^B19 | D19: =D18+C19 | E19: =(B19+1)*Vassals!$F$5 | F19: =C19/((B19)*Vassals!$F$5)
B20: 12 | C20: =$C$4*$C$5^B20 | D20: =D19+C20 | E20: =(B20+1)*Vassals!$F$5 | F20: =C20/((B20)*Vassals!$F$5)
... B58: 50 | C58: =$C$4*$C$5^B58 | D58: =D57+C58 | E58: =(B58+1)*Vassals!$F$5 | F58: =C58/((B58)*Vassals!$F$5)

Sheet Production_Sim
B1: PRODUCTION SIMULATOR (per minute)
B2: Models CC over a session. Greedy rule: each minute, buy 1 Formsworth if affordable.
B4: Starting Formsworth | C4: 0 | D4: (0 = pure manual start; first buy is the automation dopamine moment)
B5: Manual clicks / min | C5: 30
B7: Minute | C7: Owned | D7: CC/sec (auto) | E7: Manual CC/min | F7: CC gained/min | G7: CC balance
B8: 0 | C8: =C4 | D8: =C8*Vassals!$F$5 | E8: =$C$5*Assumptions!$C$10 | F8: =D8*60+E8 | G8: =F8
B9: 1 | C9: =C8+IF(G8>=(Vassals!$C$5*Vassals!$D$5^C8),1,0) | D9: =C9*Vassals!$F$5 | E9: =$C$5*Assumptions!$C$10 | F9: =D9*60+E9 | G9: =G8+F9-IF(C9>C8,(Vassals!$C$5*Vassals!$D$5^C8),0)
B10: 2 | C10: =C9+IF(G9>=(Vassals!$C$5*Vassals!$D$5^C9),1,0) | D10: =C10*Vassals!$F$5 | E10: =$C$5*Assumptions!$C$10 | F10: =D10*60+E10 | G10: =G9+F10-IF(C10>C9,(Vassals!$C$5*Vassals!$D$5^C9),0)
B11: 3 | C11: =C10+IF(G10>=(Vassals!$C$5*Vassals!$D$5^C10),1,0) | D11: =C11*Vassals!$F$5 | E11: =$C$5*Assumptions!$C$10 | F11: =D11*60+E11 | G11: =G10+F11-IF(C11>C10,(Vassals!$C$5*Vassals!$D$5^C10),0)
B12: 4 | C12: =C11+IF(G11>=(Vassals!$C$5*Vassals!$D$5^C11),1,0) | D12: =C12*Vassals!$F$5 | E12: =$C$5*Assumptions!$C$10 | F12: =D12*60+E12 | G12: =G11+F12-IF(C12>C11,(Vassals!$C$5*Vassals!$D$5^C11),0)
B13: 5 | C13: =C12+IF(G12>=(Vassals!$C$5*Vassals!$D$5^C12),1,0) | D13: =C13*Vassals!$F$5 | E13: =$C$5*Assumptions!$C$10 | F13: =D13*60+E13 | G13: =G12+F13-IF(C13>C12,(Vassals!$C$5*Vassals!$D$5^C12),0)
B14: 6 | C14: =C13+IF(G13>=(Vassals!$C$5*Vassals!$D$5^C13),1,0) | D14: =C14*Vassals!$F$5 | E14: =$C$5*Assumptions!$C$10 | F14: =D14*60+E14 | G14: =G13+F14-IF(C14>C13,(Vassals!$C$5*Vassals!$D$5^C13),0)
B15: 7 | C15: =C14+IF(G14>=(Vassals!$C$5*Vassals!$D$5^C14),1,0) | D15: =C15*Vassals!$F$5 | E15: =$C$5*Assumptions!$C$10 | F15: =D15*60+E15 | G15: =G14+F15-IF(C15>C14,(Vassals!$C$5*Vassals!$D$5^C14),0)
B16: 8 | C16: =C15+IF(G15>=(Vassals!$C$5*Vassals!$D$5^C15),1,0) | D16: =C16*Vassals!$F$5 | E16: =$C$5*Assumptions!$C$10 | F16: =D16*60+E16 | G16: =G15+F16-IF(C16>C15,(Vassals!$C$5*Vassals!$D$5^C15),0)
B17: 9 | C17: =C16+IF(G16>=(Vassals!$C$5*Vassals!$D$5^C16),1,0) | D17: =C17*Vassals!$F$5 | E17: =$C$5*Assumptions!$C$10 | F17: =D17*60+E17 | G17: =G16+F17-IF(C17>C16,(Vassals!$C$5*Vassals!$D$5^C16),0)
B18: 10 | C18: =C17+IF(G17>=(Vassals!$C$5*Vassals!$D$5^C17),1,0) | D18: =C18*Vassals!$F$5 | E18: =$C$5*Assumptions!$C$10 | F18: =D18*60+E18 | G18: =G17+F18-IF(C18>C17,(Vassals!$C$5*Vassals!$D$5^C17),0)
B19: 11 | C19: =C18+IF(G18>=(Vassals!$C$5*Vassals!$D$5^C18),1,0) | D19: =C19*Vassals!$F$5 | E19: =$C$5*Assumptions!$C$10 | F19: =D19*60+E19 | G19: =G18+F19-IF(C19>C18,(Vassals!$C$5*Vassals!$D$5^C18),0)
B20: 12 | C20: =C19+IF(G19>=(Vassals!$C$5*Vassals!$D$5^C19),1,0) | D20: =C20*Vassals!$F$5 | E20: =$C$5*Assumptions!$C$10 | F20: =D20*60+E20 | G20: =G19+F20-IF(C20>C19,(Vassals!$C$5*Vassals!$D$5^C19),0)
... B38: 30 | C38: =C37+IF(G37>=(Vassals!$C$5*Vassals!$D$5^C37),1,0) | D38: =C38*Vassals!$F$5 | E38: =$C$5*Assumptions!$C$10 | F38: =D38*60+E38 | G38: =G37+F38-IF(C38>C37,(Vassals!$C$5*Vassals!$D$5^C37),0)

Sheet Prestige_Sim
B1: PRESTIGE SIMULATOR
B2: Abdication Stamps from lifetime CC. Flat sqrt curve = diminishing returns per run (Pecorella III).
B4: Lifetime CC this run | C4: Stamps earned | D4: Total stamps (cum) | E4: Permanent buff | F4: Effect
B5: 50000 | C5: =INT((B5/Assumptions!$C$12)^Assumptions!$C$11) | D5: =C5 | E5: =D5*Assumptions!$C$13 | F5: ="+"&TEXT(E5,"0.0%")&" global production"
B6: 250000 | C6: =INT((B6/Assumptions!$C$12)^Assumptions!$C$11) | D6: =D5+C6 | E6: =D6*Assumptions!$C$13 | F6: ="+"&TEXT(E6,"0.0%")&" global production"
B7: 1000000 | C7: =INT((B7/Assumptions!$C$12)^Assumptions!$C$11) | D7: =D6+C7 | E7: =D7*Assumptions!$C$13 | F7: ="+"&TEXT(E7,"0.0%")&" global production"
B8: 5000000 | C8: =INT((B8/Assumptions!$C$12)^Assumptions!$C$11) | D8: =D7+C8 | E8: =D8*Assumptions!$C$13 | F8: ="+"&TEXT(E8,"0.0%")&" global production"
B9: 25000000 | C9: =INT((B9/Assumptions!$C$12)^Assumptions!$C$11) | D9: =D8+C9 | E9: =D9*Assumptions!$C$13 | F9: ="+"&TEXT(E9,"0.0%")&" global production"
B10: 100000000 | C10: =INT((B10/Assumptions!$C$12)^Assumptions!$C$11) | D10: =D9+C10 | E10: =D10*Assumptions!$C$13 | F10: ="+"&TEXT(E10,"0.0%")&" global production"
B11: 500000000 | C11: =INT((B11/Assumptions!$C$12)^Assumptions!$C$11) | D11: =D10+C11 | E11: =D11*Assumptions!$C$13 | F11: ="+"&TEXT(E11,"0.0%")&" global production"
B13: Tune 'Prestige divisor' & 'Prestige curve power' in Assumptions. Lower power = flatter (more diminishing).
B14: Rule of thumb: a prestige should feel worth it only after production clearly stalls (income << cost).

Sheet War_Sim
B1: WAR / CONQUEST — SECTOR GALAXY
B2: Galaxy split into sectors by tier. Same mechanics, scaled by tier. Conquering a sector unlocks the next.
B3: Tier cost scale > output scale on purpose: early conquest is quick, full galaxy takes weeks.
B5: Vrrk timer cut (hrs) | D5: =Vassals!F8 | F5: HR Muduru discount | H5: =Vassals!F9
B7: Region | C7: Tier | D7: Yields | E7: Mech-Bros | F7: Red Pill cost | G7: War timer (hrs) | H7: Base output/s | I7: Eff output/s | J7: Cumulative req
B8: — Core Sector (Tier 1) —
B9: Cor-01 | C9: 1 | D9: Sun Drips | E9: 2 | F9: =E9*Assumptions!$C$30*Assumptions!$C$31^(C9-1)*(1-$H$5) | G9: =MAX(Assumptions!$C$29*Assumptions!$C$33^(C9-1)-$D$5,1) | H9: =E9*0.4 | I9: =H9*Assumptions!$C$32^(C9-1) | J9: =F9
B10: Cor-02 | C10: 1 | D10: Pepper Melange | E10: 2 | F10: =E10*Assumptions!$C$30*Assumptions!$C$31^(C10-1)*(1-$H$5) | G10: =MAX(Assumptions!$C$29*Assumptions!$C$33^(C10-1)-$D$5,1) | H10: =E10*0.4 | I10: =H10*Assumptions!$C$32^(C10-1) | J10: =N(J9)+F10
B11: Cor-03 | C11: 1 | D11: Sun Drips | E11: 3 | F11: =E11*Assumptions!$C$30*Assumptions!$C$31^(C11-1)*(1-$H$5) | G11: =MAX(Assumptions!$C$29*Assumptions!$C$33^(C11-1)-$D$5,1) | H11: =E11*0.4 | I11: =H11*Assumptions!$C$32^(C11-1) | J11: =N(J10)+F11
B12: Cor-04 | C12: 1 | D12: Pepper Melange | E12: 3 | F12: =E12*Assumptions!$C$30*Assumptions!$C$31^(C12-1)*(1-$H$5) | G12: =MAX(Assumptions!$C$29*Assumptions!$C$33^(C12-1)-$D$5,1) | H12: =E12*0.4 | I12: =H12*Assumptions!$C$32^(C12-1) | J12: =N(J11)+F12
B13: Cor-05 | C13: 1 | D13: Sun Drips | E13: 3 | F13: =E13*Assumptions!$C$30*Assumptions!$C$31^(C13-1)*(1-$H$5) | G13: =MAX(Assumptions!$C$29*Assumptions!$C$33^(C13-1)-$D$5,1) | H13: =E13*0.4 | I13: =H13*Assumptions!$C$32^(C13-1) | J13: =N(J12)+F13
B14: Cor-06 | C14: 1 | D14: Pepper Melange | E14: 4 | F14: =E14*Assumptions!$C$30*Assumptions!$C$31^(C14-1)*(1-$H$5) | G14: =MAX(Assumptions!$C$29*Assumptions!$C$33^(C14-1)-$D$5,1) | H14: =E14*0.4 | I14: =H14*Assumptions!$C$32^(C14-1) | J14: =N(J13)+F14
B15: Cor-07 | C15: 1 | D15: Sun Drips | E15: 4 | F15: =E15*Assumptions!$C$30*Assumptions!$C$31^(C15-1)*(1-$H$5) | G15: =MAX(Assumptions!$C$29*Assumptions!$C$33^(C15-1)-$D$5,1) | H15: =E15*0.4 | I15: =H15*Assumptions!$C$32^(C15-1) | J15: =N(J14)+F15
B16: Cor-08 | C16: 1 | D16: Pepper Melange | E16: 5 | F16: =E16*Assumptions!$C$30*Assumptions!$C$31^(C16-1)*(1-$H$5) | G16: =MAX(Assumptions!$C$29*Assumptions!$C$33^(C16-1)-$D$5,1) | H16: =E16*0.4 | I16: =H16*Assumptions!$C$32^(C16-1) | J16: =N(J15)+F16
B17: Cor-09 | C17: 1 | D17: Sun Drips | E17: 5 | F17: =E17*Assumptions!$C$30*Assumptions!$C$31^(C17-1)*(1-$H$5) | G17: =MAX(Assumptions!$C$29*Assumptions!$C$33^(C17-1)-$D$5,1) | H17: =E17*0.4 | I17: =H17*Assumptions!$C$32^(C17-1) | J17: =N(J16)+F17
B18: Cor-10 | C18: 1 | D18: Pepper Melange | E18: 6 | F18: =E18*Assumptions!$C$30*Assumptions!$C$31^(C18-1)*(1-$H$5) | G18: =MAX(Assumptions!$C$29*Assumptions!$C$33^(C18-1)-$D$5,1) | H18: =E18*0.4 | I18: =H18*Assumptions!$C$32^(C18-1) | J18: =N(J17)+F18
B19: — Inner Ring Sector (Tier 2) —
B20: Inn-01 | C20: 2 | D20: Sun Drips | E20: 4 | F20: =E20*Assumptions!$C$30*Assumptions!$C$31^(C20-1)*(1-$H$5) | G20: =MAX(Assumptions!$C$29*Assumptions!$C$33^(C20-1)-$D$5,1) | H20: =E20*0.4 | I20: =H20*Assumptions!$C$32^(C20-1) | J20: =N(J19)+F20
B21: Inn-02 | C21: 2 | D21: Pepper Melange | E21: 4 | F21: =E21*Assumptions!$C$30*Assumptions!$C$31^(C21-1)*(1-$H$5) | G21: =MAX(Assumptions!$C$29*Assumptions!$C$33^(C21-1)-$D$5,1) | H21: =E21*0.4 | I21: =H21*Assumptions!$C$32^(C21-1) | J21: =N(J20)+F21
B22: Inn-03 | C22: 2 | D22: Sun Drips | E22: 5 | F22: =E22*Assumptions!$C$30*Assumptions!$C$31^(C22-1)*(1-$H$5) | G22: =MAX(Assumptions!$C$29*Assumptions!$C$33^(C22-1)-$D$5,1) | H22: =E22*0.4 | I22: =H22*Assumptions!$C$32^(C22-1) | J22: =N(J21)+F22
B23: Inn-04 | C23: 2 | D23: Pepper Melange | E23: 5 | F23: =E23*Assumptions!$C$30*Assumptions!$C$31^(C23-1)*(1-$H$5) | G23: =MAX(Assumptions!$C$29*Assumptions!$C$33^(C23-1)-$D$5,1) | H23: =E23*0.4 | I23: =H23*Assumptions!$C$32^(C23-1) | J23: =N(J22)+F23
B24: Inn-05 | C24: 2 | D24: Sun Drips | E24: 6 | F24: =E24*Assumptions!$C$30*Assumptions!$C$31^(C24-1)*(1-$H$5) | G24: =MAX(Assumptions!$C$29*Assumptions!$C$33^(C24-1)-$D$5,1) | H24: =E24*0.4 | I24: =H24*Assumptions!$C$32^(C24-1) | J24: =N(J23)+F24
B25: Inn-06 | C25: 2 | D25: Pepper Melange | E25: 6 | F25: =E25*Assumptions!$C$30*Assumptions!$C$31^(C25-1)*(1-$H$5) | G25: =MAX(Assumptions!$C$29*Assumptions!$C$33^(C25-1)-$D$5,1) | H25: =E25*0.4 | I25: =H25*Assumptions!$C$32^(C25-1) | J25: =N(J24)+F25
B26: Inn-07 | C26: 2 | D26: Sun Drips | E26: 7 | F26: =E26*Assumptions!$C$30*Assumptions!$C$31^(C26-1)*(1-$H$5) | G26: =MAX(Assumptions!$C$29*Assumptions!$C$33^(C26-1)-$D$5,1) | H26: =E26*0.4 | I26: =H26*Assumptions!$C$32^(C26-1) | J26: =N(J25)+F26
B27: Inn-08 | C27: 2 | D27: Pepper Melange | E27: 7 | F27: =E27*Assumptions!$C$30*Assumptions!$C$31^(C27-1)*(1-$H$5) | G27: =MAX(Assumptions!$C$29*Assumptions!$C$33^(C27-1)-$D$5,1) | H27: =E27*0.4 | I27: =H27*Assumptions!$C$32^(C27-1) | J27: =N(J26)+F27
B28: Inn-09 | C28: 2 | D28: Sun Drips | E28: 8 | F28: =E28*Assumptions!$C$30*Assumptions!$C$31^(C28-1)*(1-$H$5) | G28: =MAX(Assumptions!$C$29*Assumptions!$C$33^(C28-1)-$D$5,1) | H28: =E28*0.4 | I28: =H28*Assumptions!$C$32^(C28-1) | J28: =N(J27)+F28
B29: Inn-10 | C29: 2 | D29: Pepper Melange | E29: 9 | F29: =E29*Assumptions!$C$30*Assumptions!$C$31^(C29-1)*(1-$H$5) | G29: =MAX(Assumptions!$C$29*Assumptions!$C$33^(C29-1)-$D$5,1) | H29: =E29*0.4 | I29: =H29*Assumptions!$C$32^(C29-1) | J29: =N(J28)+F29
B30: — Mid Reach Sector (Tier 3) —
B31: Mid-01 | C31: 3 | D31: Sun Drips | E31: 6 | F31: =E31*Assumptions!$C$30*Assumptions!$C$31^(C31-1)*(1-$H$5) | G31: =MAX(Assumptions!$C$29*Assumptions!$C$33^(C31-1)-$D$5,1) | H31: =E31*0.4 | I31: =H31*Assumptions!$C$32^(C31-1) | J31: =N(J30)+F31
B32: Mid-02 | C32: 3 | D32: Pepper Melange | E32: 6 | F32: =E32*Assumptions!$C$30*Assumptions!$C$31^(C32-1)*(1-$H$5) | G32: =MAX(Assumptions!$C$29*Assumptions!$C$33^(C32-1)-$D$5,1) | H32: =E32*0.4 | I32: =H32*Assumptions!$C$32^(C32-1) | J32: =N(J31)+F32
B33: Mid-03 | C33: 3 | D33: Sun Drips | E33: 7 | F33: =E33*Assumptions!$C$30*Assumptions!$C$31^(C33-1)*(1-$H$5) | G33: =MAX(Assumptions!$C$29*Assumptions!$C$33^(C33-1)-$D$5,1) | H33: =E33*0.4 | I33: =H33*Assumptions!$C$32^(C33-1) | J33: =N(J32)+F33
B34: Mid-04 | C34: 3 | D34: Pepper Melange | E34: 8 | F34: =E34*Assumptions!$C$30*Assumptions!$C$31^(C34-1)*(1-$H$5) | G34: =MAX(Assumptions!$C$29*Assumptions!$C$33^(C34-1)-$D$5,1) | H34: =E34*0.4 | I34: =H34*Assumptions!$C$32^(C34-1) | J34: =N(J33)+F34
B35: Mid-05 | C35: 3 | D35: Sun Drips | E35: 9 | F35: =E35*Assumptions!$C$30*Assumptions!$C$31^(C35-1)*(1-$H$5) | G35: =MAX(Assumptions!$C$29*Assumptions!$C$33^(C35-1)-$D$5,1) | H35: =E35*0.4 | I35: =H35*Assumptions!$C$32^(C35-1) | J35: =N(J34)+F35
B36: Mid-06 | C36: 3 | D36: Pepper Melange | E36: 9 | F36: =E36*Assumptions!$C$30*Assumptions!$C$31^(C36-1)*(1-$H$5) | G36: =MAX(Assumptions!$C$29*Assumptions!$C$33^(C36-1)-$D$5,1) | H36: =E36*0.4 | I36: =H36*Assumptions!$C$32^(C36-1) | J36: =N(J35)+F36
B37: Mid-07 | C37: 3 | D37: Sun Drips | E37: 10 | F37: =E37*Assumptions!$C$30*Assumptions!$C$31^(C37-1)*(1-$H$5) | G37: =MAX(Assumptions!$C$29*Assumptions!$C$33^(C37-1)-$D$5,1) | H37: =E37*0.4 | I37: =H37*Assumptions!$C$32^(C37-1) | J37: =N(J36)+F37
B38: Mid-08 | C38: 3 | D38: Pepper Melange | E38: 11 | F38: =E38*Assumptions!$C$30*Assumptions!$C$31^(C38-1)*(1-$H$5) | G38: =MAX(Assumptions!$C$29*Assumptions!$C$33^(C38-1)-$D$5,1) | H38: =E38*0.4 | I38: =H38*Assumptions!$C$32^(C38-1) | J38: =N(J37)+F38
B39: Mid-09 | C39: 3 | D39: Sun Drips | E39: 12 | F39: =E39*Assumptions!$C$30*Assumptions!$C$31^(C39-1)*(1-$H$5) | G39: =MAX(Assumptions!$C$29*Assumptions!$C$33^(C39-1)-$D$5,1) | H39: =E39*0.4 | I39: =H39*Assumptions!$C$32^(C39-1) | J39: =N(J38)+F39
B40: Mid-10 | C40: 3 | D40: Pepper Melange | E40: 13 | F40: =E40*Assumptions!$C$30*Assumptions!$C$31^(C40-1)*(1-$H$5) | G40: =MAX(Assumptions!$C$29*Assumptions!$C$33^(C40-1)-$D$5,1) | H40: =E40*0.4 | I40: =H40*Assumptions!$C$32^(C40-1) | J40: =N(J39)+F40
B41: — Outer Rim Sector (Tier 4) —
B42: Out-01 | C42: 4 | D42: Sun Drips | E42: 9 | F42: =E42*Assumptions!$C$30*Assumptions!$C$31^(C42-1)*(1-$H$5) | G42: =MAX(Assumptions!$C$29*Assumptions!$C$33^(C42-1)-$D$5,1) | H42: =E42*0.4 | I42: =H42*Assumptions!$C$32^(C42-1) | J42: =N(J41)+F42
...

Sheet Fleet_Sim
B1: FLEET & TRANSIT VISAS
B2: Conquest needs an ARMY (Mech-Bros, Red Pill) AND LIFT (a ship with capacity, bought with Transit Visas).
B3: Transit Visas convert from CC at a steep rate. Ships are discrete goals, not a trickle.
B5: Ship | C5: Capacity (Mech-Bros) | D5: Visa cost | E5: CC cost (=Visa*rate) | F5: Unlock req | G5: Range (max tier)
B6: Shuttle | C6: 5 | D6: 1000 | E6: 100000 | F6: available at war unlock | G6: 1
B7: Frigate | C7: 30 | D7: 6000 | E7: 600000 | F7: own Shuttle | G7: 2
B8: Cruiser | C8: 120 | D8: 30000 | E8: 3000000 | F8: own Frigate | G8: 3
B9: Dreadnought | C9: 400 | D9: 150000 | E9: 15000000 | F9: own Cruiser | G9: 4
B10: Leviathan | C10: 1200 | D10: 600000 | E10: 60000000 | G10: 5
B11: CONQUEST GATE CHECK
B12: A conquest is allowed only if Mech-Bros needed <= fleet capacity AND you can pay Red Pill.
B13: Example region | C13: Mech-Bros needed | D13: Ship used | E13: Capacity | F13: Lift OK? | G13: Visa cost of ship
B14: Cor-01 (first) | C14: 3 | D14: Shuttle | E14: =C6 | F14: =IF(C14<=E14,"YES","NO - bigger ship") | G14: =D6
B15: Mid-05 | C15: 9 | D15: Shuttle | E15: =C6 | F15: =IF(C15<=E15,"YES","NO - bigger ship") | G15: =D6
B16: Out-09 | C16: 18 | D16: Frigate | E16: =C7 | F16: =IF(C16<=E16,"YES","NO - bigger ship") | G16: =D7
B17: Fri-10 | C17: 40 | D17: Cruiser | E17: =C8 | F17: =IF(C17<=E17,"YES","NO - bigger ship") | G17: =D8

Sheet UpgradeTree_Sim
B1: UPGRADE TREE
B2: Three seed branches, one of each archetype: production multiplier, time saver, cost reducer.
B3: Cost grows ~2x/level (tunable). Always something to buy -> idle loop never deadlocks.
B5: PRODUCTION: Crystal Overclock | H5: +10% global CC per level
B6: Level | C6: Cost | D6: Cumulative | E6: Cumulative effect | F6: base | G6: 100 | H6: per-level effect:
B7: 1 | C7: =$G$6*Assumptions!$C$45^(B7-1) | D7: =C7 | E7: =B7*0.1
B8: 2 | C8: =$G$6*Assumptions!$C$45^(B8-1) | D8: =D7+C8 | E8: =B8*0.1
B9: 3 | C9: =$G$6*Assumptions!$C$45^(B9-1) | D9: =D8+C9 | E9: =B9*0.1
B10: 4 | C10: =$G$6*Assumptions!$C$45^(B10-1) | D10: =D9+C10 | E10: =B10*0.1
B11: 5 | C11: =$G$6*Assumptions!$C$45^(B11-1) | D11: =D10+C11 | E11: =B11*0.1
B12: 6 | C12: =$G$6*Assumptions!$C$45^(B12-1) | D12: =D11+C12 | E12: =B12*0.1
B13: 7 | C13: =$G$6*Assumptions!$C$45^(B13-1) | D13: =D12+C13 | E13: =B13*0.1
B14: 8 | C14: =$G$6*Assumptions!$C$45^(B14-1) | D14: =D13+C14 | E14: =B14*0.1
B16: TIME: Expedited Warfare | H16: -5% war timer per level
B17: Level | C17: Cost | D17: Cumulative | E17: Cumulative effect | F17: base | G17: 250 | H17: per-level effect:
B18: 1 | C18: =$G$17*Assumptions!$C$45^(B18-1) | D18: =C18 | E18: =B18*0.05
B19: 2 | C19: =$G$17*Assumptions!$C$45^(B19-1) | D19: =D18+C19 | E19: =B19*0.05
B20: 3 | C20: =$G$17*Assumptions!$C$45^(B20-1) | D20: =D19+C20 | E20: =B20*0.05
B21: 4 | C21: =$G$17*Assumptions!$C$45^(B21-1) | D21: =D20+C21 | E21: =B21*0.05
B22: 5 | C22: =$G$17*Assumptions!$C$45^(B22-1) | D22: =D21+C22 | E22: =B22*0.05
B23: 6 | C23: =$G$17*Assumptions!$C$45^(B23-1) | D23: =D22+C23 | E23: =B23*0.05
B24: 7 | C24: =$G$17*Assumptions!$C$45^(B24-1) | D24: =D23+C24 | E24: =B24*0.05
B25: 8 | C25: =$G$17*Assumptions!$C$45^(B25-1) | D25: =D24+C25 | E25: =B25*0.05
B27: COST: Bulk Enlistment | H27: -4% Red Pill/Mech-Bro per level
B28: Level | C28: Cost | D28: Cumulative | E28: Cumulative effect | F28: base | G28: 200 | H28: per-level effect:
B29: 1 | C29: =$G$28*Assumptions!$C$45^(B29-1) | D29: =C29 | E29: =B29*0.04
B30: 2 | C30: =$G$28*Assumptions!$C$45^(B30-1) | D30: =D29+C30 | E30: =B30*0.04
B31: 3 | C31: =$G$28*Assumptions!$C$45^(B31-1) | D31: =D30+C31 | E31: =B31*0.04
B32: 4 | C32: =$G$28*Assumptions!$C$45^(B32-1) | D32: =D31+C32 | E32: =B32*0.04
B33: 5 | C33: =$G$28*Assumptions!$C$45^(B33-1) | D33: =D32+C33 | E33: =B33*0.04
B34: 6 | C34: =$G$28*Assumptions!$C$45^(B34-1) | D34: =D33+C34 | E34: =B34*0.04
B35: 7 | C35: =$G$28*Assumptions!$C$45^(B35-1) | D35: =D34+C35 | E35: =B35*0.04
B36: 8 | C36: =$G$28*Assumptions!$C$45^(B36-1) | D36: =D35+C36 | E36: =B36*0.04
B38: DESIGN: keep buying any branch -> production climbs -> affords next -> no stall (Pecorella loop).
B39: Later: gate higher tiers behind Abdication Stamps or Dark Matter for prestige-driven depth.

Sheet Connections_Sim
B1: SUN DRIPS — LOCAL CONNECTION BUFF
B2: Buff is LOCAL: each system is buffed by ITS OWN connections only. Bounded by construction.
B3: 3% per connection (cap 3 links = 9% ceiling). +5% supply-line bonus if linked to another conquered Sun Drips system.
B5: Sun Drips system | C5: Raw links | D5: Counted | E5: Linked to same-type? | F5: Local buff | G5: Buffed output/s | H5: Notes
B6: Cor-01 | C6: 2 | D6: =MIN(C6,Assumptions!$C$43) | E6: 1 | F6: =D6*Assumptions!$C$42+E6*Assumptions!$C$44 | G6: =0.8*(1+F6) | H6: cap keeps any single system <=9%+supply
B7: Cor-03 | C7: 1 | D7: =MIN(C7,Assumptions!$C$43) | E7: 0 | F7: =D7*Assumptions!$C$42+E7*Assumptions!$C$44 | G7: =1.2*(1+F7) | H7: cap keeps any single system <=9%+supply
B8: Inn-03 | C8: 4 | D8: =MIN(C8,Assumptions!$C$43) | E8: 1 | F8: =D8*Assumptions!$C$42+E8*Assumptions!$C$44 | G8: =4.8*(1+F8) | H8: cap keeps any single system <=9%+supply
B9: Mid-01 | C9: 3 | D9: =MIN(C9,Assumptions!$C$43) | E9: 1 | F9: =D9*Assumptions!$C$42+E9*Assumptions!$C$44 | G9: =8.6*(1+F9) | H9: cap keeps any single system <=9%+supply
B10: Mid-07 | C10: 5 | D10: =MIN(C10,Assumptions!$C$43) | E10: 0 | F10: =D10*Assumptions!$C$42+E10*Assumptions!$C$44 | G10: =12*(1+F10) | H10: cap keeps any single system <=9%+supply
B11: Out-05 | C11: 6 | D11: =MIN(C11,Assumptions!$C$43) | E11: 1 | F11: =D11*Assumptions!$C$42+E11*Assumptions!$C$44 | G11: =38.9*(1+F11) | H11: cap keeps any single system <=9%+supply
B12: Fri-09 | C12: 8 | D12: =MIN(C12,Assumptions!$C$43) | E12: 1 | F12: =D12*Assumptions!$C$42+E12*Assumptions!$C$44 | G12: =181.4*(1+F12) | H12: cap keeps any single system <=9%+supply
B14: Galaxy Sun Drips output (sum of buffed systems): | G14: =SUM(G6:G12)
B15: No global multiplier, no runaway: total is just the sum of locally-buffed systems.
B16: Max possible per system = (3 links x 3%) + 5% supply = 14%. That's the hard ceiling.

Sheet ResourceLadder_Sim
B1: TIERED RESOURCE LADDER
B2: Each conquered tier hands a NEW resource with a faster base rate. Not gifted -> a steeper fresh curve.
B3: As one tier's contribution flattens, the next conquest unlocks the next curve. Momentum never dies.
B5: Tier | C5: Sector | D5: Resource (TBN) | E5: Base rate/s | F5: Rate vs Tier 1 | G5: Feeds | H5: Design role
B6: 1 | C6: Core | D6: Sun Drips / Melange | E6: 0.8 | F6: =E6/$E$6 | G6: Drips->local CC buff; Melange->compound CC | H6: entry economy; teaches the loop
B7: 2 | C7: Inner | D7: Resource B | E7: =$E$6*Assumptions!$C$49^(B7-1) | F7: =E7/$E$6 | G7: fleet upgrades (cheaper Visas / capacity) | H7: makes the NEXT conquest cheaper -> snowball
B8: 3 | C8: Mid | D8: Resource C | E8: =$E$6*Assumptions!$C$49^(B8-1) | F8: =E8/$E$6 | G8: upgrade tree higher tiers | H8: deepens build variety mid-game
B9: 4 | C9: Outer | D9: Resource D | E9: =$E$6*Assumptions!$C$49^(B9-1) | F9: =E9/$E$6 | G9: Dark Matter generation | H9: bridges into prestige economy
B10: 5 | C10: Fringe | D10: Dark Matter | E10: =$E$6*Assumptions!$C$49^(B10-1) | F10: =E10/$E$6 | G10: prestige-tier multipliers / endgame | H10: apex sink; gives DM its job
B12: DARK MATTER (Fringe resource -> prestige fuel)
B13: Fringe output/s | C13: DM yield rate | D13: Dark Matter/s | E13: Role
B14: =E10 | C14: =Assumptions!$C$51 | D14: =B14*C14 | E14: DM multiplies prestige gains -> makes Abdication runs explosive
B16: DESIGN NOTES
B17: • Rate step 3x/tier: each new resource feels dramatically faster than the last -> reward for the brutal Visa gate.
B18: • Names left blank ('Resource B/C/D') on purpose -> fun naming is a later design choice.
B19: • Dark Matter is now defined: the Fringe (deepest) resource, fueling prestige multipliers. Closes the 'TBD' question.
B20: • Tune 'Resource rate step' & 'Curve flatten point' in Assumptions to set how hard each tier pulls the player onward.
B21: • Pairing: brutal conquest gate (Visas) + rich faster resource behind it = tension that makes war meaningful.

Sheet Research_Sim
B1: SHIP RESEARCH (R&D)
B2: Two gates: RESEARCH a model (CC + timer, top tiers need conquered-tier resources), then BUILD it (Visas).
B3: Shuttle is instant at war-unlock. Each model takes longer to research -> a timer is a return reason.
B5: Model | C5: Research CC | D5: Research time | E5: Resource gate | F5: Build cost (Visas) | G5: Capacity | H5: Notes
B6: Shuttle | C6: 0 | D6: 0 | E6: none | F6: 1000 | G6: 5 | H6: instant on war-unlock; the first lift
B7: Frigate | C7: 50000 | D7: 4 | E7: none | F7: 6000 | G7: 30 | H7: 4h research; first real campaign ship
B8: Cruiser | C8: 500000 | D8: 10 | E8: Tier-2 resource | F8: 30000 | G8: 120 | H8: 10h research; needs Inner-sector resource
B9: Dreadnought | C9: 5000000 | D9: 24 | E9: Tier-3 resource | F9: 150000 | G9: 400 | H9: ~1 day research; needs Mid-sector resource
B10: Leviathan | C10: 50000000 | D10: 48 | E10: Tier-4 resource | F10: 600000 | G10: 1200 | H10: 2 day research; Outer-sector resource gate
B12: Effective research time = listed time x Research speed mult (Assumptions). Vassals can cut this later.
B13: DESIGN: research timers ladder up (0/4/10/24/48h) -> fleet capacity is the conquest gate -> the prestige wall.
B14: Top models gated behind conquered-tier resources -> you must hold deep territory to unlock deeper lift.

Sheet CC_Generators
B1: COMPOUND GENERATOR CHAIN
B2: Bureaucratic hierarchy: each tier PRODUCES THE TIER BELOW IT. Only Tier 1 (Formsworth) mints CC.
B3: Production COMPOUNDS over time -> CC/s accelerates even while idle. The sci-fi self-replicating empire.
B5: Generator (vassal) | C5: Tier | D5: Produces | E5: Base rate | F5: Cost Mult | G5: Unlock | H5: Notes
B6: Lord Formsworth III | C6: 1 | D6: Cyber Crystal | E6: 1 | F6: 40 | G6: start | H6: Mints CC directly. The only one that touches a crystal.
B7: Sub-Clerk Battalion | C7: 2 | D7: Formsworths | E7: 0.05 | F7: 800 | G7: CC 5k | H7: Produces Formsworths. Interns hiring interns.
B8: Regional Datastack | C8: 3 | D8: Sub-Clerks | E8: 0.004 | F8: 60000 | G8: CC 500k | H8: Produces Sub-Clerks. Mainframe spawns floors of staff.
B9: Orbital Archive | C9: 4 | D9: Datastacks | E9: 0.00096 | F9: 9000000 | G9: conquer Inner | H9: Produces Datastacks. A moon that builds mainframes.
B10: Sector Bureaucphere | C10: 5 | D10: Archives | E10: 0.000768 | F10: 1600000000 | G10: conquer Mid | H10: Produces Archives. Planet-sized dept spawning moons.
B11: Galactic Census Engine | C11: 6 | D11: Bureaucspheres | E11: 0.000615 | F11: 320000000000 | G11: conquer Outer | H11: Produces Bureaucspheres. Self-replicating administration.
B12: The Infinite Ledger | C12: 7 | D12: Census Engines | E12: 0.000492 | F12: 72000000000000 | G12: conquer Fringe | H12: Produces Census Engines. Reality is a spreadsheet.
B14: COST MULTIPLIERS (per generator, its own curve) | C14: 1.25
B15: Lord Formsworth III | C15: 1.25
B16: Sub-Clerk Battalion | C16: 1.25
B17: Regional Datastack | C17: 1.25
B18: Orbital Archive | C18: 1.25
B19: Sector Bureaucphere | C19: 1.25
B20: Galactic Census Engine | C20: 1.25
B21: The Infinite Ledger | C21: 1.25
B23: HOW COMPOUND WORKS | C23: 1.25
B24: • Each tick: Tier N produces (count_N x base_rate_N) units of Tier N-1. Only Tier 1 produces CC. | C24: 1.25
B25: • Because higher tiers grow the lower tiers, CC/s ACCELERATES over time, not just at unlocks. | C25: 1.25
B26: • Base rate 0.10 = each unit makes 0.1 of the tier below per second (10s to make one). Tunable. | C26: 1.25
... B29: • Early tiers unlock by CC; deep tiers (Archive+) unlock by CONQUEST -> war drives economic acceleration. | C29: 1.25
